<?xml version="1.0" encoding="utf-8"?>
<!-- This URDF was automatically created by SolidWorks to URDF Exporter! Originally created by Stephen Brawner (brawner@gmail.com) 
     Commit Version: 1.6.0-4-g7f85cfe  Build Version: 1.6.7995.38578
     For more information, please see http://wiki.ros.org/sw_urdf_exporter -->
<robot
  name="robot">
  <link
    name="body_link">
    <inertial>
      <origin
        xyz="-6.2624E-18 -1.9895E-17 -3.2679E-19"
        rpy="0 0 0" />
      <mass
        value="0.972" />
      <inertia
        ixx="0.0026973"
        ixy="4.4261E-20"
        ixz="2.5292E-21"
        iyy="0.0003645"
        iyz="-2.5316E-20"
        izz="0.002916" />
    </inertial>
    <visual>
      <origin
        xyz="0 0 0"
        rpy="0 0 0" />
      <geometry>
        <mesh
          filename="package://robot/meshes/body_link.STL" />
      </geometry>
      <material
        name="">
        <color
          rgba="0.69804 0.69804 0.69804 1" />
      </material>
    </visual>
    <collision>
      <origin
        xyz="0 0 0"
        rpy="0 0 0" />
      <geometry>
        <mesh
          filename="package://robot/meshes/body_link.STL" />
      </geometry>
    </collision>
  </link>
  <link
    name="rod_link">
    <inertial>
      <origin
        xyz="-3.8548E-18 3.6953E-18 -1.3878E-17"
        rpy="0 0 0" />
      <mass
        value="0.24" />
      <inertia
        ixx="0.000808"
        ixy="-3.9104E-21"
        ixz="-3.2255E-20"
        iyy="0.000872"
        iyz="-2.4668E-20"
        izz="8E-05" />
    </inertial>
    <visual>
      <origin
        xyz="0 0 0"
        rpy="0 0 0" />
      <geometry>
        <mesh
          filename="package://robot/meshes/rod_link.STL" />
      </geometry>
      <material
        name="">
        <color
          rgba="0.79216 0.81961 0.93333 1" />
      </material>
    </visual>
    <collision>
      <origin
        xyz="0 0 0"
        rpy="0 0 0" />
      <geometry>
        <mesh
          filename="package://robot/meshes/rod_link.STL" />
      </geometry>
    </collision>
  </link>
  <joint
    name="body_rod_joint"
    type="continuous">
    <origin
      xyz="0 0 -0.115"
      rpy="0 0 0" />
    <parent
      link="body_link" />
    <child
      link="rod_link" />
    <axis
      xyz="-1 0 0" />
  </joint>
  <link
    name="wheel_link">
    <inertial>
      <origin
        xyz="-3.1898E-18 0 0"
        rpy="0 0 0" />
      <mass
        value="0.47124" />
      <inertia
        ixx="0.00058905"
        ixy="4.6673E-23"
        ixz="1.3658E-22"
        iyy="0.0004359"
        iyz="0"
        izz="0.0004359" />
    </inertial>
    <visual>
      <origin
        xyz="0 0 0"
        rpy="0 0 0" />
      <geometry>
        <mesh
          filename="package://robot/meshes/wheel_link.STL" />
      </geometry>
      <material
        name="">
        <color
          rgba="0.79216 0.81961 0.93333 1" />
      </material>
    </visual>
    <collision>
      <origin
        xyz="0 0 0"
        rpy="0 0 0" />
      <geometry>
        <mesh
          filename="package://robot/meshes/wheel_link.STL" />
      </geometry>
    </collision>
  </link>
  <joint
    name="rod_wheel_joint"
    type="continuous">
    <origin
      xyz="0 0 -0.1"
      rpy="0 0 0" />
    <parent
      link="rod_link" />
    <child
      link="wheel_link" />
    <axis
      xyz="-1 0 0" />
  </joint>
</robot>